Workbook

Sheet Inputs
A1: Inputs (blue = typed-in assumption; everything else in the workbook is a formula)
A2: Assumption | B2: F1 (golden fixture) | C2: Reference (real basis) | D2: Source / note
A3: Product | B3: LTA | C3: LTA | D3: LTA = level term; MP = mortgage protection
A4: Issue age x | B4: 35 | C4: 35 | D4: Age last birthday at issue (SPEC §2.7)
A5: Female (1/0) | B5: 0 | C5: 0
A6: Smoker (1/0) | B6: 0 | C6: 0
A7: Sum assured / initial loan (€) | B7: 250000 | C7: 250000
A8: MP loan rate | B8: 0.04 | C8: 0.04 | D8: Used only for MP (SPEC §5)
A9: Premium rate per €1,000 | B9: 2.0771311 | C9: 1.0415054 | D9: Solved in Python (brentq) for a 10% margin; Excel confirms the margin
A10: Policy fee (€ p.a.) | B10: 60 | C10: 60 | D10: SPEC §4.1
A11: Mortality multiplier | B11: 1 | C11: 0.71172986 | D11: Fixture: 1. Reference: X = 0.985^22.5 (SPEC §4.1)
A12: Fixture q at base age | B12: 0.0005 | C12: n/a (CMI 00 table) | D12: SPEC §13.3 (F1 only)
A13: Fixture base age | B13: 30 | D13: SPEC §13.3
A14: Fixture growth per year of age | B14: 1.08 | D14: SPEC §13.3
A15: Fixture female factor | B15: 0.7 | D15: SPEC §13.3
A16: Fixture smoker factor | B16: 1.8 | D16: SPEC §13.3
A17: Lapse, policy year 1 | B17: 0.06 | C17: 0.06 | D17: SPEC §4.1
A18: Lapse, policy year 2 | B18: 0.09 | C18: 0.09
A19: Lapse, policy year 3 | B19: 0.08 | C19: 0.08
A20: Lapse, policy year 4 | B20: 0.07 | C20: 0.07
A21: Lapse, policy year 5 | B21: 0.06 | C21: 0.06
A22: Lapse, year 6+ (0 in final year) | B22: 0.05 | C22: 0.05
A23: Lapse multiplier | B23: 1 | C23: 1
A24: Acquisition expense at t = 0 (€) | B24: 250 | C24: 250 | D24: SPEC §4.1
A25: Maintenance expense (€ p.a.) | B25: 60 | C25: 60
A26: Overhead (€ p.a.) | B26: 15 | C26: 15 | D26: Included here: Solvency II / pricing basis
A27: Claim expense per death (€) | B27: 250 | C27: 250
A28: Expense inflation | B28: 0.025 | C28: 0.025
A29: Initial commission (share of premium) | B29: 1 | C29: 1
A30: Reserving mortality multiplier | B30: 1.1 | C30: 1.1 | D30: SPEC §4.2: 110%, no lapses
A31: Reserving interest | B31: 0.025 | C31: 0.025 | D31: SPEC §4.2
A32: Earned rate | B32: 0.03 | C32: 0.03 | D32: SPEC §4.3
A33: Risk discount rate | B33: 0.08 | C33: 0.08 | D33: SPEC §4.3
A34: Valuation rate (flat) for V | B34: 0.03 | C34: 0.03 | D34: Flat 3%, as in the golden fixture
A35: Term (years) | B35: 20 | C35: 20
A36: SII mortality shock | B36: 0.15 | C36: 0.15 | D36: Art. 137: +15%
A37: SII lapse-up factor | B37: 1.5 | C37: 1.5 | D37: Art. 142: × 1.5
A38: SII mass lapse | B38: 0.4 | C38: 0.4 | D38: Art. 142: 40%
A39: SII expense shock | B39: 0.1 | C39: 0.1 | D39: Art. 140: +10%
A40: SII inflation shock | B40: 0.01 | C40: 0.01 | D40: Art. 140: +1pp
...

Sheet F1
A1: F1 — level term, male 35 non-smoker, €250k, 20 years (golden fixture basis)
B2: Premium (€ p.a.) | C2: =Inputs!$B$9*Inputs!$B$7/1000+Inputs!$B$10 | E2: IRR | F2: =IRR(Q8:Q27) | H2: SII loss: mortality | I2: =MAX(0,W8-L8)
B3: NPV at RDR | C3: =SUM(S8:S27) | E3: Discounted payback (years) | F3: =MIN(U8:U27) | H3: SII loss: lapse up | I3: =IF(L8<0,MAX(0,X8-L8),0)
B4: EPV of premiums at RDR | C4: =SUM(V8:V27) | E4: V at issue | F4: =L8 | H4: SII loss: mass lapse | I4: =Inputs!$B$38*MAX(0,-L8)
B5: Profit margin | C5: =C3/C4 | H5: SII loss: expense | I5: =MAX(0,Y8-L8)
H6: SII loss: catastrophe | I6: =MAX(0,K8*Inputs!$B$41*((F8+J8)-(1-D8)*L9))
A7: t | B7: Attained age | C7: q_t | D7: w_t | E7: ℓ_t (start of year) | F7: S_t | G7: Premium | H7: Commission | I7: Expenses (start) | J7: Claim expense | K7: v_t | L7: V_t best estimate | M7: q reserving | N7: V reserving | O7: Reserve _tV | P7: Profit vector Pr_t | Q7: Profit signature Π_t | R7: RDR discount | S7: PV of Π_t | T7: Cumulative PV | U7: Payback helper | V7: PV premium term | W7: V mortality +15% | X7: V lapse up ×1.5 | Y7: V expense +10%, infl +1pp
A8: 0 | B8: =Inputs!$B$4+A8 | C8: =MIN(1,Inputs!$B$11*Inputs!$B$12*Inputs!$B$14^(B8-Inputs!$B$13)*IF(Inputs!$B$5=1,Inputs!$B$15,1)*IF(Inputs!$B$6=1,Inputs!$B$16,1)) | D8: =IF(A8=Inputs!$B$35-1,0,MIN(1,Inputs!$B$23*IF(A8<5,INDEX(Inputs!$B$17:$B$21,A8+1),Inputs!$B$22))) | E8: 1 | F8: =IF(Inputs!$B$3="MP",Inputs!$B$7*(1-(1/(1+Inputs!$B$8))^(Inputs!$B$35-A8))/(1-(1/(1+Inputs!$B$8))^Inputs!$B$35),Inputs!$B$7) | G8: =$C$2 | H8: =IF(A8=0,Inputs!$B$29*G8,0) | I8: =IF(A8=0,Inputs!$B$24,0)+(Inputs!$B$25+Inputs!$B$26)*(1+Inputs!$B$28)^A8 | J8: =Inputs!$B$27*(1+Inputs!$B$28)^A8 | K8: =1/(1+Inputs!$B$34) | L8: =-G8+H8+I8+K8*(C8*(F8+J8)+(1-C8)*(1-D8)*L9) | M8: =MIN(1,C8*Inputs!$B$30) | N8: =-G8+H8+I8+(1/(1+Inputs!$B$31))*(M8*(F8+J8)+(1-M8)*N9) | O8: =IF(A8=0,0,MAX(0,N8)) | P8: =(O8+G8-H8-I8)*(1+Inputs!$B$32)-C8*(F8+J8)-(1-C8)*(1-D8)*O9 | Q8: =E8*P8 | R8: =(1+Inputs!$B$33)^-(A8+1) | S8: =Q8*R8 | T8: =SUM(S$8:S8) | U8: =IF(T8>=0,A8+1,999) | V8: =E8*G8*(1+Inputs!$B$33)^-A8 | W8: =-G8+H8+I8+K8*(MIN(1,C8*(1+Inputs!$B$36))*(F8+J8)+(1-MIN(1,C8*(1+Inputs!$B$36)))*(1-D8)*W9) | X8: =-G8+H8+I8+K8*(C8*(F8+J8)+(1-C8)*(1-MIN(1,Inputs!$B$37*D8))*X9) | Y8: =-G8+H8+(IF(A8=0,Inputs!$B$24,0)+(Inputs!$B$25+Inputs!$B$26)*(1+Inputs!$B$28+Inputs!$B$40)^A8)*(1+Inputs!$B$39)+K8*(C8*(F8+Inputs!$B$27*(1+Inputs!$B$39)*(1+Inputs!$B$28+Inputs!$B$40)^A8)+(1-C8)*(1-D8)*Y9)
A9: 1 | B9: =Inputs!$B$4+A9 | C9: =MIN(1,Inputs!$B$11*Inputs!$B$12*Inputs!$B$14^(B9-Inputs!$B$13)*IF(Inputs!$B$5=1,Inputs!$B$15,1)*IF(Inputs!$B$6=1,Inputs!$B$16,1)) | D9: =IF(A9=Inputs!$B$35-1,0,MIN(1,Inputs!$B$23*IF(A9<5,INDEX(Inputs!$B$17:$B$21,A9+1),Inputs!$B$22))) | E9: =E8*(1-C8)*(1-D8) | F9: =IF(Inputs!$B$3="MP",Inputs!$B$7*(1-(1/(1+Inputs!$B$8))^(Inputs!$B$35-A9))/(1-(1/(1+Inputs!$B$8))^Inputs!$B$35),Inputs!$B$7) | G9: =$C$2 | H9: =IF(A9=0,Inputs!$B$29*G9,0) | I9: =IF(A9=0,Inputs!$B$24,0)+(Inputs!$B$25+Inputs!$B$26)*(1+Inputs!$B$28)^A9 | J9: =Inputs!$B$27*(1+Inputs!$B$28)^A9 | K9: =1/(1+Inputs!$B$34) | L9: =-G9+H9+I9+K9*(C9*(F9+J9)+(1-C9)*(1-D9)*L10) | M9: =MIN(1,C9*Inputs!$B$30) | N9: =-G9+H9+I9+(1/(1+Inputs!$B$31))*(M9*(F9+J9)+(1-M9)*N10) | O9: =IF(A9=0,0,MAX(0,N9)) | P9: =(O9+G9-H9-I9)*(1+Inputs!$B$32)-C9*(F9+J9)-(1-C9)*(1-D9)*O10 | Q9: =E9*P9 | R9: =(1+Inputs!$B$33)^-(A9+1) | S9: =Q9*R9 | T9: =SUM(S$8:S9) | U9: =IF(T9>=0,A9+1,999) | V9: =E9*G9*(1+Inputs!$B$33)^-A9 | W9: =-G9+H9+I9+K9*(MIN(1,C9*(1+Inputs!$B$36))*(F9+J9)+(1-MIN(1,C9*(1+Inputs!$B$36)))*(1-D9)*W10) | X9: =-G9+H9+I9+K9*(C9*(F9+J9)+(1-C9)*(1-MIN(1,Inputs!$B$37*D9))*X10) | Y9: =-G9+H9+(IF(A9=0,Inputs!$B$24,0)+(Inputs!$B$25+Inputs!$B$26)*(1+Inputs!$B$28+Inputs!$B$40)^A9)*(1+Inputs!$B$39)+K9*(C9*(F9+Inputs!$B$27*(1+Inputs!$B$39)*(1+Inputs!$B$28+Inputs!$B$40)^A9)+(1-C9)*(1-D9)*Y10)
A10: 2 | B10: =Inputs!$B$4+A10 | C10: =MIN(1,Inputs!$B$11*Inputs!$B$12*Inputs!$B$14^(B10-Inputs!$B$13)*IF(Inputs!$B$5=1,Inputs!$B$15,1)*IF(Inputs!$B$6=1,Inputs!$B$16,1)) | D10: =IF(A10=Inputs!$B$35-1,0,MIN(1,Inputs!$B$23*IF(A10<5,INDEX(Inputs!$B$17:$B$21,A10+1),Inputs!$B$22))) | E10: =E9*(1-C9)*(1-D9) | F10: =IF(Inputs!$B$3="MP",Inputs!$B$7*(1-(1/(1+Inputs!$B$8))^(Inputs!$B$35-A10))/(1-(1/(1+Inputs!$B$8))^Inputs!$B$35),Inputs!$B$7) | G10: =$C$2 | H10: =IF(A10=0,Inputs!$B$29*G10,0) | I10: =IF(A10=0,Inputs!$B$24,0)+(Inputs!$B$25+Inputs!$B$26)*(1+Inputs!$B$28)^A10 | J10: =Inputs!$B$27*(1+Inputs!$B$28)^A10 | K10: =1/(1+Inputs!$B$34) | L10: =-G10+H10+I10+K10*(C10*(F10+J10)+(1-C10)*(1-D10)*L11) | M10: =MIN(1,C10*Inputs!$B$30) | N10: =-G10+H10+I10+(1/(1+Inputs!$B$31))*(M10*(F10+J10)+(1-M10)*N11) | O10: =IF(A10=0,0,MAX(0,N10)) | P10: =(O10+G10-H10-I10)*(1+Inputs!$B$32)-C10*(F10+J10)-(1-C10)*(1-D10)*O11 | Q10: =E10*P10 | R10: =(1+Inputs!$B$33)^-(A10+1) | S10: =Q10*R10 | T10: =SUM(S$8:S10) | U10: =IF(T10>=0,A10+1,999) | V10: =E10*G10*(1+Inputs!$B$33)^-A10 | W10: =-G10+H10+I10+K10*(MIN(1,C10*(1+Inputs!$B$36))*(F10+J10)+(1-MIN(1,C10*(1+Inputs!$B$36)))*(1-D10)*W11) | X10: =-G10+H10+I10+K10*(C10*(F10+J10)+(1-C10)*(1-MIN(1,Inputs!$B$37*D10))*X11) | Y10: =-G10+H10+(IF(A10=0,Inputs!$B$24,0)+(Inputs!$B$25+Inputs!$B$26)*(1+Inputs!$B$28+Inputs!$B$40)^A10)*(1+Inputs!$B$39)+K10*(C10*(F10+Inputs!$B$27*(1+Inputs!$B$39)*(1+Inputs!$B$28+Inputs!$B$40)^A10)+(1-C10)*(1-D10)*Y11)
A11: 3 | B11: =Inputs!$B$4+A11 | C11: =MIN(1,Inputs!$B$11*Inputs!$B$12*Inputs!$B$14^(B11-Inputs!$B$13)*IF(Inputs!$B$5=1,Inputs!$B$15,1)*IF(Inputs!$B$6=1,Inputs!$B$16,1)) | D11: =IF(A11=Inputs!$B$35-1,0,MIN(1,Inputs!$B$23*IF(A11<5,INDEX(Inputs!$B$17:$B$21,A11+1),Inputs!$B$22))) | E11: =E10*(1-C10)*(1-D10) | F11: =IF(Inputs!$B$3="MP",Inputs!$B$7*(1-(1/(1+Inputs!$B$8))^(Inputs!$B$35-A11))/(1-(1/(1+Inputs!$B$8))^Inputs!$B$35),Inputs!$B$7) | G11: =$C$2 | H11: =IF(A11=0,Inputs!$B$29*G11,0) | I11: =IF(A11=0,Inputs!$B$24,0)+(Inputs!$B$25+Inputs!$B$26)*(1+Inputs!$B$28)^A11 | J11: =Inputs!$B$27*(1+Inputs!$B$28)^A11 | K11: =1/(1+Inputs!$B$34) | L11: =-G11+H11+I11+K11*(C11*(F11+J11)+(1-C11)*(1-D11)*L12) | M11: =MIN(1,C11*Inputs!$B$30) | N11: =-G11+H11+I11+(1/(1+Inputs!$B$31))*(M11*(F11+J11)+(1-M11)*N12) | O11: =IF(A11=0,0,MAX(0,N11)) | P11: =(O11+G11-H11-I11)*(1+Inputs!$B$32)-C11*(F11+J11)-(1-C11)*(1-D11)*O12 | Q11: =E11*P11 | R11: =(1+Inputs!$B$33)^-(A11+1) | S11: =Q11*R11 | T11: =SUM(S$8:S11) | U11: =IF(T11>=0,A11+1,999) | V11: =E11*G11*(1+Inputs!$B$33)^-A11 | W11: =-G11+H11+I11+K11*(MIN(1,C11*(1+Inputs!$B$36))*(F11+J11)+(1-MIN(1,C11*(1+Inputs!$B$36)))*(1-D11)*W12) | X11: =-G11+H11+I11+K11*(C11*(F11+J11)+(1-C11)*(1-MIN(1,Inputs!$B$37*D11))*X12) | Y11: =-G11+H11+(IF(A11=0,Inputs!$B$24,0)+(Inputs!$B$25+Inputs!$B$26)*(1+Inputs!$B$28+Inputs!$B$40)^A11)*(1+Inputs!$B$39)+K11*(C11*(F11+Inputs!$B$27*(1+Inputs!$B$39)*(1+Inputs!$B$28+Inputs!$B$40)^A11)+(1-C11)*(1-D11)*Y12)
A12: 4 | B12: =Inputs!$B$4+A12 | C12: =MIN(1,Inputs!$B$11*Inputs!$B$12*Inputs!$B$14^(B12-Inputs!$B$13)*IF(Inputs!$B$5=1,Inputs!$B$15,1)*IF(Inputs!$B$6=1,Inputs!$B$16,1)) | D12: =IF(A12=Inputs!$B$35-1,0,MIN(1,Inputs!$B$23*IF(A12<5,INDEX(Inputs!$B$17:$B$21,A12+1),Inputs!$B$22))) | E12: =E11*(1-C11)*(1-D11) | F12: =IF(Inputs!$B$3="MP",Inputs!$B$7*(1-(1/(1+Inputs!$B$8))^(Inputs!$B$35-A12))/(1-(1/(1+Inputs!$B$8))^Inputs!$B$35),Inputs!$B$7) | G12: =$C$2 | H12: =IF(A12=0,Inputs!$B$29*G12,0) | I12: =IF(A12=0,Inputs!$B$24,0)+(Inputs!$B$25+Inputs!$B$26)*(1+Inputs!$B$28)^A12 | J12: =Inputs!$B$27*(1+Inputs!$B$28)^A12 | K12: =1/(1+Inputs!$B$34) | L12: =-G12+H12+I12+K12*(C12*(F12+J12)+(1-C12)*(1-D12)*L13) | M12: =MIN(1,C12*Inputs!$B$30) | N12: =-G12+H12+I12+(1/(1+Inputs!$B$31))*(M12*(F12+J12)+(1-M12)*N13) | O12: =IF(A12=0,0,MAX(0,N12)) | P12: =(O12+G12-H12-I12)*(1+Inputs!$B$32)-C12*(F12+J12)-(1-C12)*(1-D12)*O13 | Q12: =E12*P12 | R12: =(1+Inputs!$B$33)^-(A12+1) | S12: =Q12*R12 | T12: =SUM(S$8:S12) | U12: =IF(T12>=0,A12+1,999) | V12: =E12*G12*(1+Inputs!$B$33)^-A12 | W12: =-G12+H12+I12+K12*(MIN(1,C12*(1+Inputs!$B$36))*(F12+J12)+(1-MIN(1,C12*(1+Inputs!$B$36)))*(1-D12)*W13) | X12: =-G12+H12+I12+K12*(C12*(F12+J12)+(1-C12)*(1-MIN(1,Inputs!$B$37*D12))*X13) | Y12: =-G12+H12+(IF(A12=0,Inputs!$B$24,0)+(Inputs!$B$25+Inputs!$B$26)*(1+Inputs!$B$28+Inputs!$B$40)^A12)*(1+Inputs!$B$39)+K12*(C12*(F12+Inputs!$B$27*(1+Inputs!$B$39)*(1+Inputs!$B$28+Inputs!$B$40)^A12)+(1-C12)*(1-D12)*Y13)
A13: 5 | B13: =Inputs!$B$4+A13 | C13: =MIN(1,Inputs!$B$11*Inputs!$B$12*Inputs!$B$14^(B13-Inputs!$B$13)*IF(Inputs!$B$5=1,Inputs!$B$15,1)*IF(Inputs!$B$6=1,Inputs!$B$16,1)) | D13: =IF(A13=Inputs!$B$35-1,0,MIN(1,Inputs!$B$23*IF(A13<5,INDEX(Inputs!$B$17:$B$21,A13+1),Inputs!$B$22))) | E13: =E12*(1-C12)*(1-D12) | F13: =IF(Inputs!$B$3="MP",Inputs!$B$7*(1-(1/(1+Inputs!$B$8))^(Inputs!$B$35-A13))/(1-(1/(1+Inputs!$B$8))^Inputs!$B$35),Inputs!$B$7) | G13: =$C$2 | H13: =IF(A13=0,Inputs!$B$29*G13,0) | I13: =IF(A13=0,Inputs!$B$24,0)+(Inputs!$B$25+Inputs!$B$26)*(1+Inputs!$B$28)^A13 | J13: =Inputs!$B$27*(1+Inputs!$B$28)^A13 | K13: =1/(1+Inputs!$B$34) | L13: =-G13+H13+I13+K13*(C13*(F13+J13)+(1-C13)*(1-D13)*L14) | M13: =MIN(1,C13*Inputs!$B$30) | N13: =-G13+H13+I13+(1/(1+Inputs!$B$31))*(M13*(F13+J13)+(1-M13)*N14) | O13: =IF(A13=0,0,MAX(0,N13)) | P13: =(O13+G13-H13-I13)*(1+Inputs!$B$32)-C13*(F13+J13)-(1-C13)*(1-D13)*O14 | Q13: =E13*P13 | R13: =(1+Inputs!$B$33)^-(A13+1) | S13: =Q13*R13 | T13: =SUM(S$8:S13) | U13: =IF(T13>=0,A13+1,999) | V13: =E13*G13*(1+Inputs!$B$33)^-A13 | W13: =-G13+H13+I13+K13*(MIN(1,C13*(1+Inputs!$B$36))*(F13+J13)+(1-MIN(1,C13*(1+Inputs!$B$36)))*(1-D13)*W14) | X13: =-G13+H13+I13+K13*(C13*(F13+J13)+(1-C13)*(1-MIN(1,Inputs!$B$37*D13))*X14) | Y13: =-G13+H13+(IF(A13=0,Inputs!$B$24,0)+(Inputs!$B$25+Inputs!$B$26)*(1+Inputs!$B$28+Inputs!$B$40)^A13)*(1+Inputs!$B$39)+K13*(C13*(F13+Inputs!$B$27*(1+Inputs!$B$39)*(1+Inputs!$B$28+Inputs!$B$40)^A13)+(1-C13)*(1-D13)*Y14)
A14: 6 | B14: =Inputs!$B$4+A14 | C14: =MIN(1,Inputs!$B$11*Inputs!$B$12*Inputs!$B$14^(B14-Inputs!$B$13)*IF(Inputs!$B$5=1,Inputs!$B$15,1)*IF(Inputs!$B$6=1,Inputs!$B$16,1)) | D14: =IF(A14=Inputs!$B$35-1,0,MIN(1,Inputs!$B$23*IF(A14<5,INDEX(Inputs!$B$17:$B$21,A14+1),Inputs!$B$22))) | E14: =E13*(1-C13)*(1-D13) | F14: =IF(Inputs!$B$3="MP",Inputs!$B$7*(1-(1/(1+Inputs!$B$8))^(Inputs!$B$35-A14))/(1-(1/(1+Inputs!$B$8))^Inputs!$B$35),Inputs!$B$7) | G14: =$C$2 | H14: =IF(A14=0,Inputs!$B$29*G14,0) | I14: =IF(A14=0,Inputs!$B$24,0)+(Inputs!$B$25+Inputs!$B$26)*(1+Inputs!$B$28)^A14 | J14: =Inputs!$B$27*(1+Inputs!$B$28)^A14 | K14: =1/(1+Inputs!$B$34) | L14: =-G14+H14+I14+K14*(C14*(F14+J14)+(1-C14)*(1-D14)*L15) | M14: =MIN(1,C14*Inputs!$B$30) | N14: =-G14+H14+I14+(1/(1+Inputs!$B$31))*(M14*(F14+J14)+(1-M14)*N15) | O14: =IF(A14=0,0,MAX(0,N14)) | P14: =(O14+G14-H14-I14)*(1+Inputs!$B$32)-C14*(F14+J14)-(1-C14)*(1-D14)*O15 | Q14: =E14*P14 | R14: =(1+Inputs!$B$33)^-(A14+1) | S14: =Q14*R14 | T14: =SUM(S$8:S14) | U14: =IF(T14>=0,A14+1,999) | V14: =E14*G14*(1+Inputs!$B$33)^-A14 | W14: =-G14+H14+I14+K14*(MIN(1,C14*(1+Inputs!$B$36))*(F14+J14)+(1-MIN(1,C14*(1+Inputs!$B$36)))*(1-D14)*W15) | X14: =-G14+H14+I14+K14*(C14*(F14+J14)+(1-C14)*(1-MIN(1,Inputs!$B$37*D14))*X15) | Y14: =-G14+H14+(IF(A14=0,Inputs!$B$24,0)+(Inputs!$B$25+Inputs!$B$26)*(1+Inputs!$B$28+Inputs!$B$40)^A14)*(1+Inputs!$B$39)+K14*(C14*(F14+Inputs!$B$27*(1+Inputs!$B$39)*(1+Inputs!$B$28+Inputs!$B$40)^A14)+(1-C14)*(1-D14)*Y15)
A15: 7 | B15: =Inputs!$B$4+A15 | C15: =MIN(1,Inputs!$B$11*Inputs!$B$12*Inputs!$B$14^(B15-Inputs!$B$13)*IF(Inputs!$B$5=1,Inputs!$B$15,1)*IF(Inputs!$B$6=1,Inputs!$B$16,1)) | D15: =IF(A15=Inputs!$B$35-1,0,MIN(1,Inputs!$B$23*IF(A15<5,INDEX(Inputs!$B$17:$B$21,A15+1),Inputs!$B$22))) | E15: =E14*(1-C14)*(1-D14) | F15: =IF(Inputs!$B$3="MP",Inputs!$B$7*(1-(1/(1+Inputs!$B$8))^(Inputs!$B$35-A15))/(1-(1/(1+Inputs!$B$8))^Inputs!$B$35),Inputs!$B$7) | G15: =$C$2 | H15: =IF(A15=0,Inputs!$B$29*G15,0) | I15: =IF(A15=0,Inputs!$B$24,0)+(Inputs!$B$25+Inputs!$B$26)*(1+Inputs!$B$28)^A15 | J15: =Inputs!$B$27*(1+Inputs!$B$28)^A15 | K15: =1/(1+Inputs!$B$34) | L15: =-G15+H15+I15+K15*(C15*(F15+J15)+(1-C15)*(1-D15)*L16) | M15: =MIN(1,C15*Inputs!$B$30) | N15: =-G15+H15+I15+(1/(1+Inputs!$B$31))*(M15*(F15+J15)+(1-M15)*N16) | O15: =IF(A15=0,0,MAX(0,N15)) | P15: =(O15+G15-H15-I15)*(1+Inputs!$B$32)-C15*(F15+J15)-(1-C15)*(1-D15)*O16 | Q15: =E15*P15 | R15: =(1+Inputs!$B$33)^-(A15+1) | S15: =Q15*R15 | T15: =SUM(S$8:S15) | U15: =IF(T15>=0,A15+1,999) | V15: =E15*G15*(1+Inputs!$B$33)^-A15 | W15: =-G15+H15+I15+K15*(MIN(1,C15*(1+Inputs!$B$36))*(F15+J15)+(1-MIN(1,C15*(1+Inputs!$B$36)))*(1-D15)*W16) | X15: =-G15+H15+I15+K15*(C15*(F15+J15)+(1-C15)*(1-MIN(1,Inputs!$B$37*D15))*X16) | Y15: =-G15+H15+(IF(A15=0,Inputs!$B$24,0)+(Inputs!$B$25+Inputs!$B$26)*(1+Inputs!$B$28+Inputs!$B$40)^A15)*(1+Inputs!$B$39)+K15*(C15*(F15+Inputs!$B$27*(1+Inputs!$B$39)*(1+Inputs!$B$28+Inputs!$B$40)^A15)+(1-C15)*(1-D15)*Y16)
A16: 8 | B16: =Inputs!$B$4+A16 | C16: =MIN(1,Inputs!$B$11*Inputs!$B$12*Inputs!$B$14^(B16-Inputs!$B$13)*IF(Inputs!$B$5=1,Inputs!$B$15,1)*IF(Inputs!$B$6=1,Inputs!$B$16,1)) | D16: =IF(A16=Inputs!$B$35-1,0,MIN(1,Inputs!$B$23*IF(A16<5,INDEX(Inputs!$B$17:$B$21,A16+1),Inputs!$B$22))) | E16: =E15*(1-C15)*(1-D15) | F16: =IF(Inputs!$B$3="MP",Inputs!$B$7*(1-(1/(1+Inputs!$B$8))^(Inputs!$B$35-A16))/(1-(1/(1+Inputs!$B$8))^Inputs!$B$35),Inputs!$B$7) | G16: =$C$2 | H16: =IF(A16=0,Inputs!$B$29*G16,0) | I16: =IF(A16=0,Inputs!$B$24,0)+(Inputs!$B$25+Inputs!$B$26)*(1+Inputs!$B$28)^A16 | J16: =Inputs!$B$27*(1+Inputs!$B$28)^A16 | K16: =1/(1+Inputs!$B$34) | L16: =-G16+H16+I16+K16*(C16*(F16+J16)+(1-C16)*(1-D16)*L17) | M16: =MIN(1,C16*Inputs!$B$30) | N16: =-G16+H16+I16+(1/(1+Inputs!$B$31))*(M16*(F16+J16)+(1-M16)*N17) | O16: =IF(A16=0,0,MAX(0,N16)) | P16: =(O16+G16-H16-I16)*(1+Inputs!$B$32)-C16*(F16+J16)-(1-C16)*(1-D16)*O17 | Q16: =E16*P16 | R16: =(1+Inputs!$B$33)^-(A16+1) | S16: =Q16*R16 | T16: =SUM(S$8:S16) | U16: =IF(T16>=0,A16+1,999) | V16: =E16*G16*(1+Inputs!$B$33)^-A16 | W16: =-G16+H16+I16+K16*(MIN(1,C16*(1+Inputs!$B$36))*(F16+J16)+(1-MIN(1,C16*(1+Inputs!$B$36)))*(1-D16)*W17) | X16: =-G16+H16+I16+K16*(C16*(F16+J16)+(1-C16)*(1-MIN(1,Inputs!$B$37*D16))*X17) | Y16: =-G16+H16+(IF(A16=0,Inputs!$B$24,0)+(Inputs!$B$25+Inputs!$B$26)*(1+Inputs!$B$28+Inputs!$B$40)^A16)*(1+Inputs!$B$39)+K16*(C16*(F16+Inputs!$B$27*(1+Inputs!$B$39)*(1+Inputs!$B$28+Inputs!$B$40)^A16)+(1-C16)*(1-D16)*Y17)
A17: 9 | B17: =Inputs!$B$4+A17 | C17: =MIN(1,Inputs!$B$11*Inputs!$B$12*Inputs!$B$14^(B17-Inputs!$B$13)*IF(Inputs!$B$5=1,Inputs!$B$15,1)*IF(Inputs!$B$6=1,Inputs!$B$16,1)) | D17: =IF(A17=Inputs!$B$35-1,0,MIN(1,Inputs!$B$23*IF(A17<5,INDEX(Inputs!$B$17:$B$21,A17+1),Inputs!$B$22))) | E17: =E16*(1-C16)*(1-D16) | F17: =IF(Inputs!$B$3="MP",Inputs!$B$7*(1-(1/(1+Inputs!$B$8))^(Inputs!$B$35-A17))/(1-(1/(1+Inputs!$B$8))^Inputs!$B$35),Inputs!$B$7) | G17: =$C$2 | H17: =IF(A17=0,Inputs!$B$29*G17,0) | I17: =IF(A17=0,Inputs!$B$24,0)+(Inputs!$B$25+Inputs!$B$26)*(1+Inputs!$B$28)^A17 | J17: =Inputs!$B$27*(1+Inputs!$B$28)^A17 | K17: =1/(1+Inputs!$B$34) | L17: =-G17+H17+I17+K17*(C17*(F17+J17)+(1-C17)*(1-D17)*L18) | M17: =MIN(1,C17*Inputs!$B$30) | N17: =-G17+H17+I17+(1/(1+Inputs!$B$31))*(M17*(F17+J17)+(1-M17)*N18) | O17: =IF(A17=0,0,MAX(0,N17)) | P17: =(O17+G17-H17-I17)*(1+Inputs!$B$32)-C17*(F17+J17)-(1-C17)*(1-D17)*O18 | Q17: =E17*P17 | R17: =(1+Inputs!$B$33)^-(A17+1) | S17: =Q17*R17 | T17: =SUM(S$8:S17) | U17: =IF(T17>=0,A17+1,999) | V17: =E17*G17*(1+Inputs!$B$33)^-A17 | W17: =-G17+H17+I17+K17*(MIN(1,C17*(1+Inputs!$B$36))*(F17+J17)+(1-MIN(1,C17*(1+Inputs!$B$36)))*(1-D17)*W18) | X17: =-G17+H17+I17+K17*(C17*(F17+J17)+(1-C17)*(1-MIN(1,Inputs!$B$37*D17))*X18) | Y17: =-G17+H17+(IF(A17=0,Inputs!$B$24,0)+(Inputs!$B$25+Inputs!$B$26)*(1+Inputs!$B$28+Inputs!$B$40)^A17)*(1+Inputs!$B$39)+K17*(C17*(F17+Inputs!$B$27*(1+Inputs!$B$39)*(1+Inputs!$B$28+Inputs!$B$40)^A17)+(1-C17)*(1-D17)*Y18)
A18: 10 | B18: =Inputs!$B$4+A18 | C18: =MIN(1,Inputs!$B$11*Inputs!$B$12*Inputs!$B$14^(B18-Inputs!$B$13)*IF(Inputs!$B$5=1,Inputs!$B$15,1)*IF(Inputs!$B$6=1,Inputs!$B$16,1)) | D18: =IF(A18=Inputs!$B$35-1,0,MIN(1,Inputs!$B$23*IF(A18<5,INDEX(Inputs!$B$17:$B$21,A18+1),Inputs!$B$22))) | E18: =E17*(1-C17)*(1-D17) | F18: =IF(Inputs!$B$3="MP",Inputs!$B$7*(1-(1/(1+Inputs!$B$8))^(Inputs!$B$35-A18))/(1-(1/(1+Inputs!$B$8))^Inputs!$B$35),Inputs!$B$7) | G18: =$C$2 | H18: =IF(A18=0,Inputs!$B$29*G18,0) | I18: =IF(A18=0,Inputs!$B$24,0)+(Inputs!$B$25+Inputs!$B$26)*(1+Inputs!$B$28)^A18 | J18: =Inputs!$B$27*(1+Inputs!$B$28)^A18 | K18: =1/(1+Inputs!$B$34) | L18: =-G18+H18+I18+K18*(C18*(F18+J18)+(1-C18)*(1-D18)*L19) | M18: =MIN(1,C18*Inputs!$B$30) | N18: =-G18+H18+I18+(1/(1+Inputs!$B$31))*(M18*(F18+J18)+(1-M18)*N19) | O18: =IF(A18=0,0,MAX(0,N18)) | P18: =(O18+G18-H18-I18)*(1+Inputs!$B$32)-C18*(F18+J18)-(1-C18)*(1-D18)*O19 | Q18: =E18*P18 | R18: =(1+Inputs!$B$33)^-(A18+1) | S18: =Q18*R18 | T18: =SUM(S$8:S18) | U18: =IF(T18>=0,A18+1,999) | V18: =E18*G18*(1+Inputs!$B$33)^-A18 | W18: =-G18+H18+I18+K18*(MIN(1,C18*(1+Inputs!$B$36))*(F18+J18)+(1-MIN(1,C18*(1+Inputs!$B$36)))*(1-D18)*W19) | X18: =-G18+H18+I18+K18*(C18*(F18+J18)+(1-C18)*(1-MIN(1,Inputs!$B$37*D18))*X19) | Y18: =-G18+H18+(IF(A18=0,Inputs!$B$24,0)+(Inputs!$B$25+Inputs!$B$26)*(1+Inputs!$B$28+Inputs!$B$40)^A18)*(1+Inputs!$B$39)+K18*(C18*(F18+Inputs!$B$27*(1+Inputs!$B$39)*(1+Inputs!$B$28+Inputs!$B$40)^A18)+(1-C18)*(1-D18)*Y19)
A19: 11 | B19: =Inputs!$B$4+A19 | C19: =MIN(1,Inputs!$B$11*Inputs!$B$12*Inputs!$B$14^(B19-Inputs!$B$13)*IF(Inputs!$B$5=1,Inputs!$B$15,1)*IF(Inputs!$B$6=1,Inputs!$B$16,1)) | D19: =IF(A19=Inputs!$B$35-1,0,MIN(1,Inputs!$B$23*IF(A19<5,INDEX(Inputs!$B$17:$B$21,A19+1),Inputs!$B$22))) | E19: =E18*(1-C18)*(1-D18) | F19: =IF(Inputs!$B$3="MP",Inputs!$B$7*(1-(1/(1+Inputs!$B$8))^(Inputs!$B$35-A19))/(1-(1/(1+Inputs!$B$8))^Inputs!$B$35),Inputs!$B$7) | G19: =$C$2 | H19: =IF(A19=0,Inputs!$B$29*G19,0) | I19: =IF(A19=0,Inputs!$B$24,0)+(Inputs!$B$25+Inputs!$B$26)*(1+Inputs!$B$28)^A19 | J19: =Inputs!$B$27*(1+Inputs!$B$28)^A19 | K19: =1/(1+Inputs!$B$34) | L19: =-G19+H19+I19+K19*(C19*(F19+J19)+(1-C19)*(1-D19)*L20) | M19: =MIN(1,C19*Inputs!$B$30) | N19: =-G19+H19+I19+(1/(1+Inputs!$B$31))*(M19*(F19+J19)+(1-M19)*N20) | O19: =IF(A19=0,0,MAX(0,N19)) | P19: =(O19+G19-H19-I19)*(1+Inputs!$B$32)-C19*(F19+J19)-(1-C19)*(1-D19)*O20 | Q19: =E19*P19 | R19: =(1+Inputs!$B$33)^-(A19+1) | S19: =Q19*R19 | T19: =SUM(S$8:S19) | U19: =IF(T19>=0,A19+1,999) | V19: =E19*G19*(1+Inputs!$B$33)^-A19 | W19: =-G19+H19+I19+K19*(MIN(1,C19*(1+Inputs!$B$36))*(F19+J19)+(1-MIN(1,C19*(1+Inputs!$B$36)))*(1-D19)*W20) | X19: =-G19+H19+I19+K19*(C19*(F19+J19)+(1-C19)*(1-MIN(1,Inputs!$B$37*D19))*X20) | Y19: =-G19+H19+(IF(A19=0,Inputs!$B$24,0)+(Inputs!$B$25+Inputs!$B$26)*(1+Inputs!$B$28+Inputs!$B$40)^A19)*(1+Inputs!$B$39)+K19*(C19*(F19+Inputs!$B$27*(1+Inputs!$B$39)*(1+Inputs!$B$28+Inputs!$B$40)^A19)+(1-C19)*(1-D19)*Y20)
A20: 12 | B20: =Inputs!$B$4+A20 | C20: =MIN(1,Inputs!$B$11*Inputs!$B$12*Inputs!$B$14^(B20-Inputs!$B$13)*IF(Inputs!$B$5=1,Inputs!$B$15,1)*IF(Inputs!$B$6=1,Inputs!$B$16,1)) | D20: =IF(A20=Inputs!$B$35-1,0,MIN(1,Inputs!$B$23*IF(A20<5,INDEX(Inputs!$B$17:$B$21,A20+1),Inputs!$B$22))) | E20: =E19*(1-C19)*(1-D19) | F20: =IF(Inputs!$B$3="MP",Inputs!$B$7*(1-(1/(1+Inputs!$B$8))^(Inputs!$B$35-A20))/(1-(1/(1+Inputs!$B$8))^Inputs!$B$35),Inputs!$B$7) | G20: =$C$2 | H20: =IF(A20=0,Inputs!$B$29*G20,0) | I20: =IF(A20=0,Inputs!$B$24,0)+(Inputs!$B$25+Inputs!$B$26)*(1+Inputs!$B$28)^A20 | J20: =Inputs!$B$27*(1+Inputs!$B$28)^A20 | K20: =1/(1+Inputs!$B$34) | L20: =-G20+H20+I20+K20*(C20*(F20+J20)+(1-C20)*(1-D20)*L21) | M20: =MIN(1,C20*Inputs!$B$30) | N20: =-G20+H20+I20+(1/(1+Inputs!$B$31))*(M20*(F20+J20)+(1-M20)*N21) | O20: =IF(A20=0,0,MAX(0,N20)) | P20: =(O20+G20-H20-I20)*(1+Inputs!$B$32)-C20*(F20+J20)-(1-C20)*(1-D20)*O21 | Q20: =E20*P20 | R20: =(1+Inputs!$B$33)^-(A20+1) | S20: =Q20*R20 | T20: =SUM(S$8:S20) | U20: =IF(T20>=0,A20+1,999) | V20: =E20*G20*(1+Inputs!$B$33)^-A20 | W20: =-G20+H20+I20+K20*(MIN(1,C20*(1+Inputs!$B$36))*(F20+J20)+(1-MIN(1,C20*(1+Inputs!$B$36)))*(1-D20)*W21) | X20: =-G20+H20+I20+K20*(C20*(F20+J20)+(1-C20)*(1-MIN(1,Inputs!$B$37*D20))*X21) | Y20: =-G20+H20+(IF(A20=0,Inputs!$B$24,0)+(Inputs!$B$25+Inputs!$B$26)*(1+Inputs!$B$28+Inputs!$B$40)^A20)*(1+Inputs!$B$39)+K20*(C20*(F20+Inputs!$B$27*(1+Inputs!$B$39)*(1+Inputs!$B$28+Inputs!$B$40)^A20)+(1-C20)*(1-D20)*Y21)
... A27: 19 | B27: =Inputs!$B$4+A27 | C27: =MIN(1,Inputs!$B$11*Inputs!$B$12*Inputs!$B$14^(B27-Inputs!$B$13)*IF(Inputs!$B$5=1,Inputs!$B$15,1)*IF(Inputs!$B$6=1,Inputs!$B$16,1)) | D27: =IF(A27=Inputs!$B$35-1,0,MIN(1,Inputs!$B$23*IF(A27<5,INDEX(Inputs!$B$17:$B$21,A27+1),Inputs!$B$22))) | E27: =E26*(1-C26)*(1-D26) | F27: =IF(Inputs!$B$3="MP",Inputs!$B$7*(1-(1/(1+Inputs!$B$8))^(Inputs!$B$35-A27))/(1-(1/(1+Inputs!$B$8))^Inputs!$B$35),Inputs!$B$7) | G27: =$C$2 | H27: =IF(A27=0,Inputs!$B$29*G27,0) | I27: =IF(A27=0,Inputs!$B$24,0)+(Inputs!$B$25+Inputs!$B$26)*(1+Inputs!$B$28)^A27 | J27: =Inputs!$B$27*(1+Inputs!$B$28)^A27 | K27: =1/(1+Inputs!$B$34) | L27: =-G27+H27+I27+K27*(C27*(F27+J27)+(1-C27)*(1-D27)*L28) | M27: =MIN(1,C27*Inputs!$B$30) | N27: =-G27+H27+I27+(1/(1+Inputs!$B$31))*(M27*(F27+J27)+(1-M27)*N28) | O27: =IF(A27=0,0,MAX(0,N27)) | P27: =(O27+G27-H27-I27)*(1+Inputs!$B$32)-C27*(F27+J27)-(1-C27)*(1-D27)*O28 | Q27: =E27*P27 | R27: =(1+Inputs!$B$33)^-(A27+1) | S27: =Q27*R27 | T27: =SUM(S$8:S27) | U27: =IF(T27>=0,A27+1,999) | V27: =E27*G27*(1+Inputs!$B$33)^-A27 | W27: =-G27+H27+I27+K27*(MIN(1,C27*(1+Inputs!$B$36))*(F27+J27)+(1-MIN(1,C27*(1+Inputs!$B$36)))*(1-D27)*W28) | X27: =-G27+H27+I27+K27*(C27*(F27+J27)+(1-C27)*(1-MIN(1,Inputs!$B$37*D27))*X28) | Y27: =-G27+H27+(IF(A27=0,Inputs!$B$24,0)+(Inputs!$B$25+Inputs!$B$26)*(1+Inputs!$B$28+Inputs!$B$40)^A27)*(1+Inputs!$B$39)+K27*(C27*(F27+Inputs!$B$27*(1+Inputs!$B$39)*(1+Inputs!$B$28+Inputs!$B$40)^A27)+(1-C27)*(1-D27)*Y28)
A28: 20 | B28: =Inputs!$B$4+A28 | E28: =E27*(1-C27)*(1-D27) | L28: 0 | N28: 0 | O28: 0 | W28: 0 | X28: 0 | Y28: 0
A30: Timing (SPEC §2.2): premium, commission and expenses at the start of each policy year; claims and claim expenses at the end; lapses at the end, after deaths. V is computed backwards from V_20 = 0.

Sheet Reference
A1: Reference — level term, male 35 non-smoker, €250k, 20 years (real basis: CMI 00 × X, unisex rate)
B2: Premium (€ p.a.) | C2: =Inputs!$C$9*Inputs!$C$7/1000+Inputs!$C$10 | E2: IRR | F2: =IRR(Q8:Q27) | H2: SII loss: mortality | I2: =MAX(0,W8-L8)
B3: NPV at RDR | C3: =SUM(S8:S27) | E3: Discounted payback (years) | F3: =MIN(U8:U27) | H3: SII loss: lapse up | I3: =IF(L8<0,MAX(0,X8-L8),0)
B4: EPV of premiums at RDR | C4: =SUM(V8:V27) | E4: V at issue | F4: =L8 | H4: SII loss: mass lapse | I4: =Inputs!$C$38*MAX(0,-L8)
B5: Profit margin | C5: =C3/C4 | H5: SII loss: expense | I5: =MAX(0,Y8-L8)
H6: SII loss: catastrophe | I6: =MAX(0,K8*Inputs!$C$41*((F8+J8)-(1-D8)*L9))
A7: t | B7: Attained age | C7: q_t | D7: w_t | E7: ℓ_t (start of year) | F7: S_t | G7: Premium | H7: Commission | I7: Expenses (start) | J7: Claim expense | K7: v_t | L7: V_t best estimate | M7: q reserving | N7: V reserving | O7: Reserve _tV | P7: Profit vector Pr_t | Q7: Profit signature Π_t | R7: RDR discount | S7: PV of Π_t | T7: Cumulative PV | U7: Payback helper | V7: PV premium term | W7: V mortality +15% | X7: V lapse up ×1.5 | Y7: V expense +10%, infl +1pp
A8: 0 | B8: =Inputs!$C$4+A8 | C8: =MIN(1,Inputs!$C$11*INDEX(CMI_TMN00!$B$3:$G$106,MATCH(B8,CMI_TMN00!$A$3:$A$106,0),MIN(A8,5)+1)) | D8: =IF(A8=Inputs!$C$35-1,0,MIN(1,Inputs!$C$23*IF(A8<5,INDEX(Inputs!$C$17:$C$21,A8+1),Inputs!$C$22))) | E8: 1 | F8: =IF(Inputs!$C$3="MP",Inputs!$C$7*(1-(1/(1+Inputs!$C$8))^(Inputs!$C$35-A8))/(1-(1/(1+Inputs!$C$8))^Inputs!$C$35),Inputs!$C$7) | G8: =$C$2 | H8: =IF(A8=0,Inputs!$C$29*G8,0) | I8: =IF(A8=0,Inputs!$C$24,0)+(Inputs!$C$25+Inputs!$C$26)*(1+Inputs!$C$28)^A8 | J8: =Inputs!$C$27*(1+Inputs!$C$28)^A8 | K8: =1/(1+Inputs!$C$34) | L8: =-G8+H8+I8+K8*(C8*(F8+J8)+(1-C8)*(1-D8)*L9) | M8: =MIN(1,C8*Inputs!$C$30) | N8: =-G8+H8+I8+(1/(1+Inputs!$C$31))*(M8*(F8+J8)+(1-M8)*N9) | O8: =IF(A8=0,0,MAX(0,N8)) | P8: =(O8+G8-H8-I8)*(1+Inputs!$C$32)-C8*(F8+J8)-(1-C8)*(1-D8)*O9 | Q8: =E8*P8 | R8: =(1+Inputs!$C$33)^-(A8+1) | S8: =Q8*R8 | T8: =SUM(S$8:S8) | U8: =IF(T8>=0,A8+1,999) | V8: =E8*G8*(1+Inputs!$C$33)^-A8 | W8: =-G8+H8+I8+K8*(MIN(1,C8*(1+Inputs!$C$36))*(F8+J8)+(1-MIN(1,C8*(1+Inputs!$C$36)))*(1-D8)*W9) | X8: =-G8+H8+I8+K8*(C8*(F8+J8)+(1-C8)*(1-MIN(1,Inputs!$C$37*D8))*X9) | Y8: =-G8+H8+(IF(A8=0,Inputs!$C$24,0)+(Inputs!$C$25+Inputs!$C$26)*(1+Inputs!$C$28+Inputs!$C$40)^A8)*(1+Inputs!$C$39)+K8*(C8*(F8+Inputs!$C$27*(1+Inputs!$C$39)*(1+Inputs!$C$28+Inputs!$C$40)^A8)+(1-C8)*(1-D8)*Y9)
A9: 1 | B9: =Inputs!$C$4+A9 | C9: =MIN(1,Inputs!$C$11*INDEX(CMI_TMN00!$B$3:$G$106,MATCH(B9,CMI_TMN00!$A$3:$A$106,0),MIN(A9,5)+1)) | D9: =IF(A9=Inputs!$C$35-1,0,MIN(1,Inputs!$C$23*IF(A9<5,INDEX(Inputs!$C$17:$C$21,A9+1),Inputs!$C$22))) | E9: =E8*(1-C8)*(1-D8) | F9: =IF(Inputs!$C$3="MP",Inputs!$C$7*(1-(1/(1+Inputs!$C$8))^(Inputs!$C$35-A9))/(1-(1/(1+Inputs!$C$8))^Inputs!$C$35),Inputs!$C$7) | G9: =$C$2 | H9: =IF(A9=0,Inputs!$C$29*G9,0) | I9: =IF(A9=0,Inputs!$C$24,0)+(Inputs!$C$25+Inputs!$C$26)*(1+Inputs!$C$28)^A9 | J9: =Inputs!$C$27*(1+Inputs!$C$28)^A9 | K9: =1/(1+Inputs!$C$34) | L9: =-G9+H9+I9+K9*(C9*(F9+J9)+(1-C9)*(1-D9)*L10) | M9: =MIN(1,C9*Inputs!$C$30) | N9: =-G9+H9+I9+(1/(1+Inputs!$C$31))*(M9*(F9+J9)+(1-M9)*N10) | O9: =IF(A9=0,0,MAX(0,N9)) | P9: =(O9+G9-H9-I9)*(1+Inputs!$C$32)-C9*(F9+J9)-(1-C9)*(1-D9)*O10 | Q9: =E9*P9 | R9: =(1+Inputs!$C$33)^-(A9+1) | S9: =Q9*R9 | T9: =SUM(S$8:S9) | U9: =IF(T9>=0,A9+1,999) | V9: =E9*G9*(1+Inputs!$C$33)^-A9 | W9: =-G9+H9+I9+K9*(MIN(1,C9*(1+Inputs!$C$36))*(F9+J9)+(1-MIN(1,C9*(1+Inputs!$C$36)))*(1-D9)*W10) | X9: =-G9+H9+I9+K9*(C9*(F9+J9)+(1-C9)*(1-MIN(1,Inputs!$C$37*D9))*X10) | Y9: =-G9+H9+(IF(A9=0,Inputs!$C$24,0)+(Inputs!$C$25+Inputs!$C$26)*(1+Inputs!$C$28+Inputs!$C$40)^A9)*(1+Inputs!$C$39)+K9*(C9*(F9+Inputs!$C$27*(1+Inputs!$C$39)*(1+Inputs!$C$28+Inputs!$C$40)^A9)+(1-C9)*(1-D9)*Y10)
A10: 2 | B10: =Inputs!$C$4+A10 | C10: =MIN(1,Inputs!$C$11*INDEX(CMI_TMN00!$B$3:$G$106,MATCH(B10,CMI_TMN00!$A$3:$A$106,0),MIN(A10,5)+1)) | D10: =IF(A10=Inputs!$C$35-1,0,MIN(1,Inputs!$C$23*IF(A10<5,INDEX(Inputs!$C$17:$C$21,A10+1),Inputs!$C$22))) | E10: =E9*(1-C9)*(1-D9) | F10: =IF(Inputs!$C$3="MP",Inputs!$C$7*(1-(1/(1+Inputs!$C$8))^(Inputs!$C$35-A10))/(1-(1/(1+Inputs!$C$8))^Inputs!$C$35),Inputs!$C$7) | G10: =$C$2 | H10: =IF(A10=0,Inputs!$C$29*G10,0) | I10: =IF(A10=0,Inputs!$C$24,0)+(Inputs!$C$25+Inputs!$C$26)*(1+Inputs!$C$28)^A10 | J10: =Inputs!$C$27*(1+Inputs!$C$28)^A10 | K10: =1/(1+Inputs!$C$34) | L10: =-G10+H10+I10+K10*(C10*(F10+J10)+(1-C10)*(1-D10)*L11) | M10: =MIN(1,C10*Inputs!$C$30) | N10: =-G10+H10+I10+(1/(1+Inputs!$C$31))*(M10*(F10+J10)+(1-M10)*N11) | O10: =IF(A10=0,0,MAX(0,N10)) | P10: =(O10+G10-H10-I10)*(1+Inputs!$C$32)-C10*(F10+J10)-(1-C10)*(1-D10)*O11 | Q10: =E10*P10 | R10: =(1+Inputs!$C$33)^-(A10+1) | S10: =Q10*R10 | T10: =SUM(S$8:S10) | U10: =IF(T10>=0,A10+1,999) | V10: =E10*G10*(1+Inputs!$C$33)^-A10 | W10: =-G10+H10+I10+K10*(MIN(1,C10*(1+Inputs!$C$36))*(F10+J10)+(1-MIN(1,C10*(1+Inputs!$C$36)))*(1-D10)*W11) | X10: =-G10+H10+I10+K10*(C10*(F10+J10)+(1-C10)*(1-MIN(1,Inputs!$C$37*D10))*X11) | Y10: =-G10+H10+(IF(A10=0,Inputs!$C$24,0)+(Inputs!$C$25+Inputs!$C$26)*(1+Inputs!$C$28+Inputs!$C$40)^A10)*(1+Inputs!$C$39)+K10*(C10*(F10+Inputs!$C$27*(1+Inputs!$C$39)*(1+Inputs!$C$28+Inputs!$C$40)^A10)+(1-C10)*(1-D10)*Y11)
A11: 3 | B11: =Inputs!$C$4+A11 | C11: =MIN(1,Inputs!$C$11*INDEX(CMI_TMN00!$B$3:$G$106,MATCH(B11,CMI_TMN00!$A$3:$A$106,0),MIN(A11,5)+1)) | D11: =IF(A11=Inputs!$C$35-1,0,MIN(1,Inputs!$C$23*IF(A11<5,INDEX(Inputs!$C$17:$C$21,A11+1),Inputs!$C$22))) | E11: =E10*(1-C10)*(1-D10) | F11: =IF(Inputs!$C$3="MP",Inputs!$C$7*(1-(1/(1+Inputs!$C$8))^(Inputs!$C$35-A11))/(1-(1/(1+Inputs!$C$8))^Inputs!$C$35),Inputs!$C$7) | G11: =$C$2 | H11: =IF(A11=0,Inputs!$C$29*G11,0) | I11: =IF(A11=0,Inputs!$C$24,0)+(Inputs!$C$25+Inputs!$C$26)*(1+Inputs!$C$28)^A11 | J11: =Inputs!$C$27*(1+Inputs!$C$28)^A11 | K11: =1/(1+Inputs!$C$34) | L11: =-G11+H11+I11+K11*(C11*(F11+J11)+(1-C11)*(1-D11)*L12) | M11: =MIN(1,C11*Inputs!$C$30) | N11: =-G11+H11+I11+(1/(1+Inputs!$C$31))*(M11*(F11+J11)+(1-M11)*N12) | O11: =IF(A11=0,0,MAX(0,N11)) | P11: =(O11+G11-H11-I11)*(1+Inputs!$C$32)-C11*(F11+J11)-(1-C11)*(1-D11)*O12 | Q11: =E11*P11 | R11: =(1+Inputs!$C$33)^-(A11+1) | S11: =Q11*R11 | T11: =SUM(S$8:S11) | U11: =IF(T11>=0,A11+1,999) | V11: =E11*G11*(1+Inputs!$C$33)^-A11 | W11: =-G11+H11+I11+K11*(MIN(1,C11*(1+Inputs!$C$36))*(F11+J11)+(1-MIN(1,C11*(1+Inputs!$C$36)))*(1-D11)*W12) | X11: =-G11+H11+I11+K11*(C11*(F11+J11)+(1-C11)*(1-MIN(1,Inputs!$C$37*D11))*X12) | Y11: =-G11+H11+(IF(A11=0,Inputs!$C$24,0)+(Inputs!$C$25+Inputs!$C$26)*(1+Inputs!$C$28+Inputs!$C$40)^A11)*(1+Inputs!$C$39)+K11*(C11*(F11+Inputs!$C$27*(1+Inputs!$C$39)*(1+Inputs!$C$28+Inputs!$C$40)^A11)+(1-C11)*(1-D11)*Y12)
A12: 4 | B12: =Inputs!$C$4+A12 | C12: =MIN(1,Inputs!$C$11*INDEX(CMI_TMN00!$B$3:$G$106,MATCH(B12,CMI_TMN00!$A$3:$A$106,0),MIN(A12,5)+1)) | D12: =IF(A12=Inputs!$C$35-1,0,MIN(1,Inputs!$C$23*IF(A12<5,INDEX(Inputs!$C$17:$C$21,A12+1),Inputs!$C$22))) | E12: =E11*(1-C11)*(1-D11) | F12: =IF(Inputs!$C$3="MP",Inputs!$C$7*(1-(1/(1+Inputs!$C$8))^(Inputs!$C$35-A12))/(1-(1/(1+Inputs!$C$8))^Inputs!$C$35),Inputs!$C$7) | G12: =$C$2 | H12: =IF(A12=0,Inputs!$C$29*G12,0) | I12: =IF(A12=0,Inputs!$C$24,0)+(Inputs!$C$25+Inputs!$C$26)*(1+Inputs!$C$28)^A12 | J12: =Inputs!$C$27*(1+Inputs!$C$28)^A12 | K12: =1/(1+Inputs!$C$34) | L12: =-G12+H12+I12+K12*(C12*(F12+J12)+(1-C12)*(1-D12)*L13) | M12: =MIN(1,C12*Inputs!$C$30) | N12: =-G12+H12+I12+(1/(1+Inputs!$C$31))*(M12*(F12+J12)+(1-M12)*N13) | O12: =IF(A12=0,0,MAX(0,N12)) | P12: =(O12+G12-H12-I12)*(1+Inputs!$C$32)-C12*(F12+J12)-(1-C12)*(1-D12)*O13 | Q12: =E12*P12 | R12: =(1+Inputs!$C$33)^-(A12+1) | S12: =Q12*R12 | T12: =SUM(S$8:S12) | U12: =IF(T12>=0,A12+1,999) | V12: =E12*G12*(1+Inputs!$C$33)^-A12 | W12: =-G12+H12+I12+K12*(MIN(1,C12*(1+Inputs!$C$36))*(F12+J12)+(1-MIN(1,C12*(1+Inputs!$C$36)))*(1-D12)*W13) | X12: =-G12+H12+I12+K12*(C12*(F12+J12)+(1-C12)*(1-MIN(1,Inputs!$C$37*D12))*X13) | Y12: =-G12+H12+(IF(A12=0,Inputs!$C$24,0)+(Inputs!$C$25+Inputs!$C$26)*(1+Inputs!$C$28+Inputs!$C$40)^A12)*(1+Inputs!$C$39)+K12*(C12*(F12+Inputs!$C$27*(1+Inputs!$C$39)*(1+Inputs!$C$28+Inputs!$C$40)^A12)+(1-C12)*(1-D12)*Y13)
A13: 5 | B13: =Inputs!$C$4+A13 | C13: =MIN(1,Inputs!$C$11*INDEX(CMI_TMN00!$B$3:$G$106,MATCH(B13,CMI_TMN00!$A$3:$A$106,0),MIN(A13,5)+1)) | D13: =IF(A13=Inputs!$C$35-1,0,MIN(1,Inputs!$C$23*IF(A13<5,INDEX(Inputs!$C$17:$C$21,A13+1),Inputs!$C$22))) | E13: =E12*(1-C12)*(1-D12) | F13: =IF(Inputs!$C$3="MP",Inputs!$C$7*(1-(1/(1+Inputs!$C$8))^(Inputs!$C$35-A13))/(1-(1/(1+Inputs!$C$8))^Inputs!$C$35),Inputs!$C$7) | G13: =$C$2 | H13: =IF(A13=0,Inputs!$C$29*G13,0) | I13: =IF(A13=0,Inputs!$C$24,0)+(Inputs!$C$25+Inputs!$C$26)*(1+Inputs!$C$28)^A13 | J13: =Inputs!$C$27*(1+Inputs!$C$28)^A13 | K13: =1/(1+Inputs!$C$34) | L13: =-G13+H13+I13+K13*(C13*(F13+J13)+(1-C13)*(1-D13)*L14) | M13: =MIN(1,C13*Inputs!$C$30) | N13: =-G13+H13+I13+(1/(1+Inputs!$C$31))*(M13*(F13+J13)+(1-M13)*N14) | O13: =IF(A13=0,0,MAX(0,N13)) | P13: =(O13+G13-H13-I13)*(1+Inputs!$C$32)-C13*(F13+J13)-(1-C13)*(1-D13)*O14 | Q13: =E13*P13 | R13: =(1+Inputs!$C$33)^-(A13+1) | S13: =Q13*R13 | T13: =SUM(S$8:S13) | U13: =IF(T13>=0,A13+1,999) | V13: =E13*G13*(1+Inputs!$C$33)^-A13 | W13: =-G13+H13+I13+K13*(MIN(1,C13*(1+Inputs!$C$36))*(F13+J13)+(1-MIN(1,C13*(1+Inputs!$C$36)))*(1-D13)*W14) | X13: =-G13+H13+I13+K13*(C13*(F13+J13)+(1-C13)*(1-MIN(1,Inputs!$C$37*D13))*X14) | Y13: =-G13+H13+(IF(A13=0,Inputs!$C$24,0)+(Inputs!$C$25+Inputs!$C$26)*(1+Inputs!$C$28+Inputs!$C$40)^A13)*(1+Inputs!$C$39)+K13*(C13*(F13+Inputs!$C$27*(1+Inputs!$C$39)*(1+Inputs!$C$28+Inputs!$C$40)^A13)+(1-C13)*(1-D13)*Y14)
A14: 6 | B14: =Inputs!$C$4+A14 | C14: =MIN(1,Inputs!$C$11*INDEX(CMI_TMN00!$B$3:$G$106,MATCH(B14,CMI_TMN00!$A$3:$A$106,0),MIN(A14,5)+1)) | D14: =IF(A14=Inputs!$C$35-1,0,MIN(1,Inputs!$C$23*IF(A14<5,INDEX(Inputs!$C$17:$C$21,A14+1),Inputs!$C$22))) | E14: =E13*(1-C13)*(1-D13) | F14: =IF(Inputs!$C$3="MP",Inputs!$C$7*(1-(1/(1+Inputs!$C$8))^(Inputs!$C$35-A14))/(1-(1/(1+Inputs!$C$8))^Inputs!$C$35),Inputs!$C$7) | G14: =$C$2 | H14: =IF(A14=0,Inputs!$C$29*G14,0) | I14: =IF(A14=0,Inputs!$C$24,0)+(Inputs!$C$25+Inputs!$C$26)*(1+Inputs!$C$28)^A14 | J14: =Inputs!$C$27*(1+Inputs!$C$28)^A14 | K14: =1/(1+Inputs!$C$34) | L14: =-G14+H14+I14+K14*(C14*(F14+J14)+(1-C14)*(1-D14)*L15) | M14: =MIN(1,C14*Inputs!$C$30) | N14: =-G14+H14+I14+(1/(1+Inputs!$C$31))*(M14*(F14+J14)+(1-M14)*N15) | O14: =IF(A14=0,0,MAX(0,N14)) | P14: =(O14+G14-H14-I14)*(1+Inputs!$C$32)-C14*(F14+J14)-(1-C14)*(1-D14)*O15 | Q14: =E14*P14 | R14: =(1+Inputs!$C$33)^-(A14+1) | S14: =Q14*R14 | T14: =SUM(S$8:S14) | U14: =IF(T14>=0,A14+1,999) | V14: =E14*G14*(1+Inputs!$C$33)^-A14 | W14: =-G14+H14+I14+K14*(MIN(1,C14*(1+Inputs!$C$36))*(F14+J14)+(1-MIN(1,C14*(1+Inputs!$C$36)))*(1-D14)*W15) | X14: =-G14+H14+I14+K14*(C14*(F14+J14)+(1-C14)*(1-MIN(1,Inputs!$C$37*D14))*X15) | Y14: =-G14+H14+(IF(A14=0,Inputs!$C$24,0)+(Inputs!$C$25+Inputs!$C$26)*(1+Inputs!$C$28+Inputs!$C$40)^A14)*(1+Inputs!$C$39)+K14*(C14*(F14+Inputs!$C$27*(1+Inputs!$C$39)*(1+Inputs!$C$28+Inputs!$C$40)^A14)+(1-C14)*(1-D14)*Y15)
A15: 7 | B15: =Inputs!$C$4+A15 | C15: =MIN(1,Inputs!$C$11*INDEX(CMI_TMN00!$B$3:$G$106,MATCH(B15,CMI_TMN00!$A$3:$A$106,0),MIN(A15,5)+1)) | D15: =IF(A15=Inputs!$C$35-1,0,MIN(1,Inputs!$C$23*IF(A15<5,INDEX(Inputs!$C$17:$C$21,A15+1),Inputs!$C$22))) | E15: =E14*(1-C14)*(1-D14) | F15: =IF(Inputs!$C$3="MP",Inputs!$C$7*(1-(1/(1+Inputs!$C$8))^(Inputs!$C$35-A15))/(1-(1/(1+Inputs!$C$8))^Inputs!$C$35),Inputs!$C$7) | G15: =$C$2 | H15: =IF(A15=0,Inputs!$C$29*G15,0) | I15: =IF(A15=0,Inputs!$C$24,0)+(Inputs!$C$25+Inputs!$C$26)*(1+Inputs!$C$28)^A15 | J15: =Inputs!$C$27*(1+Inputs!$C$28)^A15 | K15: =1/(1+Inputs!$C$34) | L15: =-G15+H15+I15+K15*(C15*(F15+J15)+(1-C15)*(1-D15)*L16) | M15: =MIN(1,C15*Inputs!$C$30) | N15: =-G15+H15+I15+(1/(1+Inputs!$C$31))*(M15*(F15+J15)+(1-M15)*N16) | O15: =IF(A15=0,0,MAX(0,N15)) | P15: =(O15+G15-H15-I15)*(1+Inputs!$C$32)-C15*(F15+J15)-(1-C15)*(1-D15)*O16 | Q15: =E15*P15 | R15: =(1+Inputs!$C$33)^-(A15+1) | S15: =Q15*R15 | T15: =SUM(S$8:S15) | U15: =IF(T15>=0,A15+1,999) | V15: =E15*G15*(1+Inputs!$C$33)^-A15 | W15: =-G15+H15+I15+K15*(MIN(1,C15*(1+Inputs!$C$36))*(F15+J15)+(1-MIN(1,C15*(1+Inputs!$C$36)))*(1-D15)*W16) | X15: =-G15+H15+I15+K15*(C15*(F15+J15)+(1-C15)*(1-MIN(1,Inputs!$C$37*D15))*X16) | Y15: =-G15+H15+(IF(A15=0,Inputs!$C$24,0)+(Inputs!$C$25+Inputs!$C$26)*(1+Inputs!$C$28+Inputs!$C$40)^A15)*(1+Inputs!$C$39)+K15*(C15*(F15+Inputs!$C$27*(1+Inputs!$C$39)*(1+Inputs!$C$28+Inputs!$C$40)^A15)+(1-C15)*(1-D15)*Y16)
A16: 8 | B16: =Inputs!$C$4+A16 | C16: =MIN(1,Inputs!$C$11*INDEX(CMI_TMN00!$B$3:$G$106,MATCH(B16,CMI_TMN00!$A$3:$A$106,0),MIN(A16,5)+1)) | D16: =IF(A16=Inputs!$C$35-1,0,MIN(1,Inputs!$C$23*IF(A16<5,INDEX(Inputs!$C$17:$C$21,A16+1),Inputs!$C$22))) | E16: =E15*(1-C15)*(1-D15) | F16: =IF(Inputs!$C$3="MP",Inputs!$C$7*(1-(1/(1+Inputs!$C$8))^(Inputs!$C$35-A16))/(1-(1/(1+Inputs!$C$8))^Inputs!$C$35),Inputs!$C$7) | G16: =$C$2 | H16: =IF(A16=0,Inputs!$C$29*G16,0) | I16: =IF(A16=0,Inputs!$C$24,0)+(Inputs!$C$25+Inputs!$C$26)*(1+Inputs!$C$28)^A16 | J16: =Inputs!$C$27*(1+Inputs!$C$28)^A16 | K16: =1/(1+Inputs!$C$34) | L16: =-G16+H16+I16+K16*(C16*(F16+J16)+(1-C16)*(1-D16)*L17) | M16: =MIN(1,C16*Inputs!$C$30) | N16: =-G16+H16+I16+(1/(1+Inputs!$C$31))*(M16*(F16+J16)+(1-M16)*N17) | O16: =IF(A16=0,0,MAX(0,N16)) | P16: =(O16+G16-H16-I16)*(1+Inputs!$C$32)-C16*(F16+J16)-(1-C16)*(1-D16)*O17 | Q16: =E16*P16 | R16: =(1+Inputs!$C$33)^-(A16+1) | S16: =Q16*R16 | T16: =SUM(S$8:S16) | U16: =IF(T16>=0,A16+1,999) | V16: =E16*G16*(1+Inputs!$C$33)^-A16 | W16: =-G16+H16+I16+K16*(MIN(1,C16*(1+Inputs!$C$36))*(F16+J16)+(1-MIN(1,C16*(1+Inputs!$C$36)))*(1-D16)*W17) | X16: =-G16+H16+I16+K16*(C16*(F16+J16)+(1-C16)*(1-MIN(1,Inputs!$C$37*D16))*X17) | Y16: =-G16+H16+(IF(A16=0,Inputs!$C$24,0)+(Inputs!$C$25+Inputs!$C$26)*(1+Inputs!$C$28+Inputs!$C$40)^A16)*(1+Inputs!$C$39)+K16*(C16*(F16+Inputs!$C$27*(1+Inputs!$C$39)*(1+Inputs!$C$28+Inputs!$C$40)^A16)+(1-C16)*(1-D16)*Y17)
A17: 9 | B17: =Inputs!$C$4+A17 | C17: =MIN(1,Inputs!$C$11*INDEX(CMI_TMN00!$B$3:$G$106,MATCH(B17,CMI_TMN00!$A$3:$A$106,0),MIN(A17,5)+1)) | D17: =IF(A17=Inputs!$C$35-1,0,MIN(1,Inputs!$C$23*IF(A17<5,INDEX(Inputs!$C$17:$C$21,A17+1),Inputs!$C$22))) | E17: =E16*(1-C16)*(1-D16) | F17: =IF(Inputs!$C$3="MP",Inputs!$C$7*(1-(1/(1+Inputs!$C$8))^(Inputs!$C$35-A17))/(1-(1/(1+Inputs!$C$8))^Inputs!$C$35),Inputs!$C$7) | G17: =$C$2 | H17: =IF(A17=0,Inputs!$C$29*G17,0) | I17: =IF(A17=0,Inputs!$C$24,0)+(Inputs!$C$25+Inputs!$C$26)*(1+Inputs!$C$28)^A17 | J17: =Inputs!$C$27*(1+Inputs!$C$28)^A17 | K17: =1/(1+Inputs!$C$34) | L17: =-G17+H17+I17+K17*(C17*(F17+J17)+(1-C17)*(1-D17)*L18) | M17: =MIN(1,C17*Inputs!$C$30) | N17: =-G17+H17+I17+(1/(1+Inputs!$C$31))*(M17*(F17+J17)+(1-M17)*N18) | O17: =IF(A17=0,0,MAX(0,N17)) | P17: =(O17+G17-H17-I17)*(1+Inputs!$C$32)-C17*(F17+J17)-(1-C17)*(1-D17)*O18 | Q17: =E17*P17 | R17: =(1+Inputs!$C$33)^-(A17+1) | S17: =Q17*R17 | T17: =SUM(S$8:S17) | U17: =IF(T17>=0,A17+1,999) | V17: =E17*G17*(1+Inputs!$C$33)^-A17 | W17: =-G17+H17+I17+K17*(MIN(1,C17*(1+Inputs!$C$36))*(F17+J17)+(1-MIN(1,C17*(1+Inputs!$C$36)))*(1-D17)*W18) | X17: =-G17+H17+I17+K17*(C17*(F17+J17)+(1-C17)*(1-MIN(1,Inputs!$C$37*D17))*X18) | Y17: =-G17+H17+(IF(A17=0,Inputs!$C$24,0)+(Inputs!$C$25+Inputs!$C$26)*(1+Inputs!$C$28+Inputs!$C$40)^A17)*(1+Inputs!$C$39)+K17*(C17*(F17+Inputs!$C$27*(1+Inputs!$C$39)*(1+Inputs!$C$28+Inputs!$C$40)^A17)+(1-C17)*(1-D17)*Y18)
A18: 10 | B18: =Inputs!$C$4+A18 | C18: =MIN(1,Inputs!$C$11*INDEX(CMI_TMN00!$B$3:$G$106,MATCH(B18,CMI_TMN00!$A$3:$A$106,0),MIN(A18,5)+1)) | D18: =IF(A18=Inputs!$C$35-1,0,MIN(1,Inputs!$C$23*IF(A18<5,INDEX(Inputs!$C$17:$C$21,A18+1),Inputs!$C$22))) | E18: =E17*(1-C17)*(1-D17) | F18: =IF(Inputs!$C$3="MP",Inputs!$C$7*(1-(1/(1+Inputs!$C$8))^(Inputs!$C$35-A18))/(1-(1/(1+Inputs!$C$8))^Inputs!$C$35),Inputs!$C$7) | G18: =$C$2 | H18: =IF(A18=0,Inputs!$C$29*G18,0) | I18: =IF(A18=0,Inputs!$C$24,0)+(Inputs!$C$25+Inputs!$C$26)*(1+Inputs!$C$28)^A18 | J18: =Inputs!$C$27*(1+Inputs!$C$28)^A18 | K18: =1/(1+Inputs!$C$34) | L18: =-G18+H18+I18+K18*(C18*(F18+J18)+(1-C18)*(1-D18)*L19) | M18: =MIN(1,C18*Inputs!$C$30) | N18: =-G18+H18+I18+(1/(1+Inputs!$C$31))*(M18*(F18+J18)+(1-M18)*N19) | O18: =IF(A18=0,0,MAX(0,N18)) | P18: =(O18+G18-H18-I18)*(1+Inputs!$C$32)-C18*(F18+J18)-(1-C18)*(1-D18)*O19 | Q18: =E18*P18 | R18: =(1+Inputs!$C$33)^-(A18+1) | S18: =Q18*R18 | T18: =SUM(S$8:S18) | U18: =IF(T18>=0,A18+1,999) | V18: =E18*G18*(1+Inputs!$C$33)^-A18 | W18: =-G18+H18+I18+K18*(MIN(1,C18*(1+Inputs!$C$36))*(F18+J18)+(1-MIN(1,C18*(1+Inputs!$C$36)))*(1-D18)*W19) | X18: =-G18+H18+I18+K18*(C18*(F18+J18)+(1-C18)*(1-MIN(1,Inputs!$C$37*D18))*X19) | Y18: =-G18+H18+(IF(A18=0,Inputs!$C$24,0)+(Inputs!$C$25+Inputs!$C$26)*(1+Inputs!$C$28+Inputs!$C$40)^A18)*(1+Inputs!$C$39)+K18*(C18*(F18+Inputs!$C$27*(1+Inputs!$C$39)*(1+Inputs!$C$28+Inputs!$C$40)^A18)+(1-C18)*(1-D18)*Y19)
A19: 11 | B19: =Inputs!$C$4+A19 | C19: =MIN(1,Inputs!$C$11*INDEX(CMI_TMN00!$B$3:$G$106,MATCH(B19,CMI_TMN00!$A$3:$A$106,0),MIN(A19,5)+1)) | D19: =IF(A19=Inputs!$C$35-1,0,MIN(1,Inputs!$C$23*IF(A19<5,INDEX(Inputs!$C$17:$C$21,A19+1),Inputs!$C$22))) | E19: =E18*(1-C18)*(1-D18) | F19: =IF(Inputs!$C$3="MP",Inputs!$C$7*(1-(1/(1+Inputs!$C$8))^(Inputs!$C$35-A19))/(1-(1/(1+Inputs!$C$8))^Inputs!$C$35),Inputs!$C$7) | G19: =$C$2 | H19: =IF(A19=0,Inputs!$C$29*G19,0) | I19: =IF(A19=0,Inputs!$C$24,0)+(Inputs!$C$25+Inputs!$C$26)*(1+Inputs!$C$28)^A19 | J19: =Inputs!$C$27*(1+Inputs!$C$28)^A19 | K19: =1/(1+Inputs!$C$34) | L19: =-G19+H19+I19+K19*(C19*(F19+J19)+(1-C19)*(1-D19)*L20) | M19: =MIN(1,C19*Inputs!$C$30) | N19: =-G19+H19+I19+(1/(1+Inputs!$C$31))*(M19*(F19+J19)+(1-M19)*N20) | O19: =IF(A19=0,0,MAX(0,N19)) | P19: =(O19+G19-H19-I19)*(1+Inputs!$C$32)-C19*(F19+J19)-(1-C19)*(1-D19)*O20 | Q19: =E19*P19 | R19: =(1+Inputs!$C$33)^-(A19+1) | S19: =Q19*R19 | T19: =SUM(S$8:S19) | U19: =IF(T19>=0,A19+1,999) | V19: =E19*G19*(1+Inputs!$C$33)^-A19 | W19: =-G19+H19+I19+K19*(MIN(1,C19*(1+Inputs!$C$36))*(F19+J19)+(1-MIN(1,C19*(1+Inputs!$C$36)))*(1-D19)*W20) | X19: =-G19+H19+I19+K19*(C19*(F19+J19)+(1-C19)*(1-MIN(1,Inputs!$C$37*D19))*X20) | Y19: =-G19+H19+(IF(A19=0,Inputs!$C$24,0)+(Inputs!$C$25+Inputs!$C$26)*(1+Inputs!$C$28+Inputs!$C$40)^A19)*(1+Inputs!$C$39)+K19*(C19*(F19+Inputs!$C$27*(1+Inputs!$C$39)*(1+Inputs!$C$28+Inputs!$C$40)^A19)+(1-C19)*(1-D19)*Y20)
A20: 12 | B20: =Inputs!$C$4+A20 | C20: =MIN(1,Inputs!$C$11*INDEX(CMI_TMN00!$B$3:$G$106,MATCH(B20,CMI_TMN00!$A$3:$A$106,0),MIN(A20,5)+1)) | D20: =IF(A20=Inputs!$C$35-1,0,MIN(1,Inputs!$C$23*IF(A20<5,INDEX(Inputs!$C$17:$C$21,A20+1),Inputs!$C$22))) | E20: =E19*(1-C19)*(1-D19) | F20: =IF(Inputs!$C$3="MP",Inputs!$C$7*(1-(1/(1+Inputs!$C$8))^(Inputs!$C$35-A20))/(1-(1/(1+Inputs!$C$8))^Inputs!$C$35),Inputs!$C$7) | G20: =$C$2 | H20: =IF(A20=0,Inputs!$C$29*G20,0) | I20: =IF(A20=0,Inputs!$C$24,0)+(Inputs!$C$25+Inputs!$C$26)*(1+Inputs!$C$28)^A20 | J20: =Inputs!$C$27*(1+Inputs!$C$28)^A20 | K20: =1/(1+Inputs!$C$34) | L20: =-G20+H20+I20+K20*(C20*(F20+J20)+(1-C20)*(1-D20)*L21) | M20: =MIN(1,C20*Inputs!$C$30) | N20: =-G20+H20+I20+(1/(1+Inputs!$C$31))*(M20*(F20+J20)+(1-M20)*N21) | O20: =IF(A20=0,0,MAX(0,N20)) | P20: =(O20+G20-H20-I20)*(1+Inputs!$C$32)-C20*(F20+J20)-(1-C20)*(1-D20)*O21 | Q20: =E20*P20 | R20: =(1+Inputs!$C$33)^-(A20+1) | S20: =Q20*R20 | T20: =SUM(S$8:S20) | U20: =IF(T20>=0,A20+1,999) | V20: =E20*G20*(1+Inputs!$C$33)^-A20 | W20: =-G20+H20+I20+K20*(MIN(1,C20*(1+Inputs!$C$36))*(F20+J20)+(1-MIN(1,C20*(1+Inputs!$C$36)))*(1-D20)*W21) | X20: =-G20+H20+I20+K20*(C20*(F20+J20)+(1-C20)*(1-MIN(1,Inputs!$C$37*D20))*X21) | Y20: =-G20+H20+(IF(A20=0,Inputs!$C$24,0)+(Inputs!$C$25+Inputs!$C$26)*(1+Inputs!$C$28+Inputs!$C$40)^A20)*(1+Inputs!$C$39)+K20*(C20*(F20+Inputs!$C$27*(1+Inputs!$C$39)*(1+Inputs!$C$28+Inputs!$C$40)^A20)+(1-C20)*(1-D20)*Y21)
... A27: 19 | B27: =Inputs!$C$4+A27 | C27: =MIN(1,Inputs!$C$11*INDEX(CMI_TMN00!$B$3:$G$106,MATCH(B27,CMI_TMN00!$A$3:$A$106,0),MIN(A27,5)+1)) | D27: =IF(A27=Inputs!$C$35-1,0,MIN(1,Inputs!$C$23*IF(A27<5,INDEX(Inputs!$C$17:$C$21,A27+1),Inputs!$C$22))) | E27: =E26*(1-C26)*(1-D26) | F27: =IF(Inputs!$C$3="MP",Inputs!$C$7*(1-(1/(1+Inputs!$C$8))^(Inputs!$C$35-A27))/(1-(1/(1+Inputs!$C$8))^Inputs!$C$35),Inputs!$C$7) | G27: =$C$2 | H27: =IF(A27=0,Inputs!$C$29*G27,0) | I27: =IF(A27=0,Inputs!$C$24,0)+(Inputs!$C$25+Inputs!$C$26)*(1+Inputs!$C$28)^A27 | J27: =Inputs!$C$27*(1+Inputs!$C$28)^A27 | K27: =1/(1+Inputs!$C$34) | L27: =-G27+H27+I27+K27*(C27*(F27+J27)+(1-C27)*(1-D27)*L28) | M27: =MIN(1,C27*Inputs!$C$30) | N27: =-G27+H27+I27+(1/(1+Inputs!$C$31))*(M27*(F27+J27)+(1-M27)*N28) | O27: =IF(A27=0,0,MAX(0,N27)) | P27: =(O27+G27-H27-I27)*(1+Inputs!$C$32)-C27*(F27+J27)-(1-C27)*(1-D27)*O28 | Q27: =E27*P27 | R27: =(1+Inputs!$C$33)^-(A27+1) | S27: =Q27*R27 | T27: =SUM(S$8:S27) | U27: =IF(T27>=0,A27+1,999) | V27: =E27*G27*(1+Inputs!$C$33)^-A27 | W27: =-G27+H27+I27+K27*(MIN(1,C27*(1+Inputs!$C$36))*(F27+J27)+(1-MIN(1,C27*(1+Inputs!$C$36)))*(1-D27)*W28) | X27: =-G27+H27+I27+K27*(C27*(F27+J27)+(1-C27)*(1-MIN(1,Inputs!$C$37*D27))*X28) | Y27: =-G27+H27+(IF(A27=0,Inputs!$C$24,0)+(Inputs!$C$25+Inputs!$C$26)*(1+Inputs!$C$28+Inputs!$C$40)^A27)*(1+Inputs!$C$39)+K27*(C27*(F27+Inputs!$C$27*(1+Inputs!$C$39)*(1+Inputs!$C$28+Inputs!$C$40)^A27)+(1-C27)*(1-D27)*Y28)
A28: 20 | B28: =Inputs!$C$4+A28 | E28: =E27*(1-C27)*(1-D27) | L28: 0 | N28: 0 | O28: 0 | W28: 0 | X28: 0 | Y28: 0
A30: Timing (SPEC §2.2): premium, commission and expenses at the start of each policy year; claims and claim expenses at the end; lapses at the end, after deaths. V is computed backwards from V_20 = 0.

Sheet CMI_TMN00
A1: CMI 00 series, TMN00 (temporary assurances, male non-smokers), q[x−t]+t by attained age. Source: IFoA.
A2: Attained age | B2: Dur 0 | C2: Dur 1 | D2: Dur 2 | E2: Dur 3 | F2: Dur 4 | G2: Dur 5+
A3: 17 | B3: 0.000159 | C3: 0.000206 | D3: 0.000242 | E3: 0.000277 | F3: 0.000313 | G3: 0.000363
A4: 18 | B4: 0.00016 | C4: 0.000207 | D4: 0.000243 | E4: 0.000279 | F4: 0.000314 | G4: 0.000365
A5: 19 | B5: 0.000161 | C5: 0.000209 | D5: 0.000245 | E5: 0.000281 | F5: 0.000317 | G5: 0.000368
A6: 20 | B6: 0.000163 | C6: 0.000211 | D6: 0.000248 | E6: 0.000284 | F6: 0.00032 | G6: 0.000372
A7: 21 | B7: 0.000164 | C7: 0.000213 | D7: 0.00025 | E7: 0.000286 | F7: 0.000323 | G7: 0.000375
A8: 22 | B8: 0.000166 | C8: 0.000216 | D8: 0.000253 | E8: 0.00029 | F8: 0.000327 | G8: 0.00038
A9: 23 | B9: 0.000168 | C9: 0.000218 | D9: 0.000256 | E9: 0.000293 | F9: 0.000331 | G9: 0.000384
A10: 24 | B10: 0.00017 | C10: 0.000221 | D10: 0.00026 | E10: 0.000298 | F10: 0.000336 | G10: 0.00039
A11: 25 | B11: 0.000173 | C11: 0.000225 | D11: 0.000264 | E11: 0.000302 | F11: 0.000341 | G11: 0.000396
A12: 26 | B12: 0.000176 | C12: 0.000229 | D12: 0.000268 | E12: 0.000308 | F12: 0.000347 | G12: 0.000403
A13: 27 | B13: 0.00018 | C13: 0.000233 | D13: 0.000274 | E13: 0.000314 | F13: 0.000354 | G13: 0.000411
A14: 28 | B14: 0.000184 | C14: 0.000239 | D14: 0.00028 | E14: 0.000321 | F14: 0.000363 | G14: 0.000421
... A76: 90 | B76: 0.051022 | C76: 0.070291 | D76: 0.084765 | E76: 0.09924 | F76: 0.113714 | G76: 0.153168
A77: 91 | C77: 0.076901 | D77: 0.092736 | E77: 0.108572 | F77: 0.124407 | G77: 0.167571
A78: 92 | D78: 0.101291 | E78: 0.118587 | F78: 0.135883 | G78: 0.183029
A79: 93 | E79: 0.129306 | F79: 0.148166 | G79: 0.199573
A80: 94 | F80: 0.161276 | G80: 0.217232
A81: 95 | G81: 0.236024
A82: 96 | G82: 0.255963
A83: 97 | G83: 0.277048
A84: 98 | G84: 0.299269
A85: 99 | G85: 0.322606
A86: 100 | G86: 0.346759
A87: 101 | G87: 0.370214
A88: 102 | G88: 0.392528
A89: 103 | G89: 0.413752
A90: 104 | G90: 0.433932
A91: 105 | G91: 0.45311
A92: 106 | G92: 0.471326
... A106: 120 | G106: 1

Sheet Check_F1
A1: Reconciliation: F1 vs the Python model (tolerance €0.01)
A2: Green = formula from the model sheet; black numbers = Python values; difference = Excel − Python.
A4: Item | B4: Excel | C4: Python | D4: Difference
A5: Premium | B5: =F1!C2 | C5: 579.28276 | D5: =B5-C5
A6: NPV | B6: =F1!C3 | C6: 408.16561 | D6: =B6-C6
A7: Profit margin | B7: =F1!C5 | C7: 0.1 | D7: =B7-C7
A8: IRR | B8: =F1!F2 | C8: 0.30247678 | D8: =B8-C8
A9: V at issue | B9: =F1!F4 | C9: -689.22699 | D9: =B9-C9
A10: SII loss: mortality | B10: =F1!I2 | C10: 461.11828 | D10: =B10-C10
A11: SII loss: lapse_up | B11: =F1!I3 | C11: 105.09716 | D11: =B11-C11
A12: SII loss: mass | B12: =F1!I4 | C12: 275.69079 | D12: =B12-C12
A13: SII loss: expense | B13: =F1!I5 | C13: 180.34461 | D13: =B13-C13
A14: SII loss: cat | B14: =F1!I6 | C14: 366.23215 | D14: =B14-C14
A17: t | B17: ℓ_t Excel | C17: ℓ_t Python | D17: ℓ_t Diff | E17: V_t Excel | F17: V_t Python | G17: V_t Diff | H17: Reserve Excel | I17: Reserve Python | J17: Reserve Diff | K17: Profit vector Excel | L17: Profit vector Python | M17: Profit vector Diff
A18: 0 | B18: =F1!E8 | C18: 1 | D18: =B18-C18 | E18: =F1!L8 | F18: -689.22699 | G18: =E18-F18 | H18: =F1!O8 | I18: 0 | J18: =H18-I18 | K18: =F1!P8 | L18: -518.59968 | M18: =K18-L18
A19: 1 | B19: =F1!E9 | C19: 0.93930942 | D19: =B19-C19 | E19: =F1!L9 | F19: -1307.8794 | G19: =E19-F19 | H19: =F1!O9 | I19: 0 | J19: =H19-I19 | K19: =F1!P9 | L19: 318.91739 | M19: =K19-L19
A20: 2 | B20: =F1!E10 | C20: 0.85409336 | D20: =B20-C20 | E20: =F1!L10 | F20: -1130.7856 | G20: =E20-F20 | H20: =F1!O10 | I20: 0 | J20: =H20-I20 | K20: =F1!P10 | L20: 301.04736 | M20: =K20-L20
A21: 3 | B21: =F1!E11 | C21: 0.78509256 | D21: =B21-C21 | E21: =F1!L11 | F21: -939.56796 | G21: =E21-F21 | H21: =F1!O11 | I21: 0 | J21: =H21-I21 | K21: =F1!P11 | L21: 194.16852 | M21: =K21-L21
A22: 4 | B22: =F1!E12 | C22: 0.72946037 | D22: =B22-C22 | E22: =F1!L12 | F22: -738.20898 | G22: =E22-F22 | H22: =F1!O12 | I22: 94.374964 | J22: =H22-I22 | K22: =F1!P12 | L22: 47.767036 | M22: =K22-L22
A23: 5 | B23: =F1!E13 | C23: 0.68500739 | D23: =B23-C23 | E23: =F1!L13 | F23: -531.50459 | G23: =E23-F23 | H23: =F1!O13 | I23: 330.84076 | J23: =H23-I23 | K23: =F1!P13 | L23: 58.522676 | M23: =K23-L23
A24: 6 | B24: =F1!E14 | C24: 0.65005455 | D24: =B24-C24 | E24: =F1!L14 | F24: -324.94099 | G24: =E24-F24 | H24: =F1!O14 | I24: 549.36388 | J24: =H24-I24 | K24: =F1!P14 | L24: 71.641787 | M24: =K24-L24
A25: 7 | B25: =F1!E15 | C25: 0.61683187 | D25: =B25-C25 | E25: =F1!L15 | F25: -125.83846 | G25: =E25-F25 | H25: =F1!O15 | I25: 747.69807 | J25: =H25-I25 | K25: =F1!P15 | L25: 83.698998 | M25: =K25-L25
A26: 8 | B26: =F1!E16 | C26: 0.58525247 | D26: =B26-C26 | E26: =F1!L16 | F26: 63.317863 | G26: =E26-F26 | H26: =F1!O16 | I26: 923.39405 | J26: =H26-I26 | K26: =F1!P16 | L26: 94.563243 | M26: =K26-L26
A27: 9 | B27: =F1!E17 | C27: 0.5552338 | D27: =B27-C27 | E27: =F1!L17 | F27: 239.68367 | G27: =E27-F27 | H27: =F1!O17 | I27: 1073.7813 | J27: =H27-I27 | K27: =F1!P17 | L27: 104.0917 | M27: =K27-L27
A28: 10 | B28: =F1!E18 | C28: 0.52669747 | D28: =B28-C28 | E28: =F1!L18 | F28: 400.0117 | G28: =E28-F28 | H28: =F1!O18 | I28: 1195.9478 | J28: =H28-I28 | K28: =F1!P18 | L28: 112.12878 | M28: =K28-L28
A29: 11 | B29: =F1!E19 | C29: 0.49956898 | D29: =B29-C29 | E29: =F1!L19 | F29: 540.60276 | G29: =E29-F29 | H29: =F1!O19 | I29: 1286.7182 | J29: =H29-I29 | K29: =F1!P19 | L29: 118.50491 | M29: =K29-L29
... A37: 19 | B37: =F1!E27 | C37: 0.32543335 | D37: =B37-C37 | E37: =F1!L27 | F37: 311.40703 | G37: =E37-F37 | H37: =F1!O27 | I37: 392.62208 | J37: =H37-I37 | K37: =F1!P27 | L37: 83.651506 | M37: =K37-L37
A39: Largest absolute difference | B39: =MAX(MAX(ABS(MIN(D5:D14)),ABS(MAX(D5:D14))),MAX(ABS(MIN(D18:D37)),ABS(MAX(D18:D37))),MAX(ABS(MIN(G18:G37)),ABS(MAX(G18:G37))),MAX(ABS(MIN(J18:J37)),ABS(MAX(J18:J37))),MAX(ABS(MIN(M18:M37)),ABS(MAX(M18:M37))))
A40: Reconciled within €0.01? | B40: =IF(B39<0.01,"YES","NO")

Sheet Check_Reference
A1: Reconciliation: Reference vs the Python model (tolerance €0.01)
A2: Green = formula from the model sheet; black numbers = Python values; difference = Excel − Python.
A4: Item | B4: Excel | C4: Python | D4: Difference
A5: Premium | B5: =Reference!C2 | C5: 320.37636 | D5: =B5-C5
A6: NPV | B6: =Reference!C3 | C6: 93.449403 | D6: =B6-C6
A7: Profit margin | B7: =Reference!C5 | C7: 0.041251628 | D7: =B7-C7
A8: IRR | B8: =Reference!F2 | C8: 0.14005188 | D8: =B8-C8
A9: V at issue | B9: =Reference!F4 | C9: -238.53716 | D9: =B9-C9
A10: SII loss: mortality | B10: =Reference!I2 | C10: 205.04189 | D10: =B10-C10
A11: SII loss: lapse_up | B11: =Reference!I3 | C11: 38.490428 | D11: =B11-C11
A12: SII loss: mass | B12: =Reference!I4 | C12: 95.414866 | D12: =B12-C12
A13: SII loss: expense | B13: =Reference!I5 | C13: 180.94091 | D13: =B13-C13
A14: SII loss: cat | B14: =Reference!I6 | C14: 365.35492 | D14: =B14-C14
A17: t | B17: ℓ_t Excel | C17: ℓ_t Python | D17: ℓ_t Diff | E17: V_t Excel | F17: V_t Python | G17: V_t Diff | H17: Reserve Excel | I17: Reserve Python | J17: Reserve Diff | K17: Profit vector Excel | L17: Profit vector Python | M17: Profit vector Diff
A18: 0 | B18: =Reference!E8 | C18: 1 | D18: =B18-C18 | E18: =Reference!L8 | F18: -238.53716 | G18: =E18-F18 | H18: =Reference!O8 | I18: 0 | J18: =H18-I18 | K18: =Reference!P8 | L18: -381.23681 | M18: =K18-L18
A19: 1 | B19: =Reference!E9 | C19: 0.93982538 | D19: =B19-C19 | E19: =Reference!L9 | F19: -667.07082 | G19: =E19-F19 | H19: =Reference!O9 | I19: 0 | J19: =H19-I19 | K19: =Reference!P9 | L19: 188.4662 | M19: =K19-L19
A20: 2 | B20: =Reference!E10 | C20: 0.85502805 | D20: =B20-C20 | E20: =Reference!L10 | F20: -548.06702 | G20: =E20-F20 | H20: =Reference!O10 | I20: 0 | J20: =H20-I20 | K20: =Reference!P10 | L20: 142.34522 | M20: =K20-L20
A21: 3 | B21: =Reference!E11 | C21: 0.78638507 | D21: =B21-C21 | E21: =Reference!L11 | F21: -426.51477 | G21: =E21-F21 | H21: =Reference!O11 | I21: 32.49941 | J21: =H21-I21 | K21: =Reference!P11 | L21: 23.000448 | M21: =K21-L21
A22: 4 | B22: =Reference!E12 | C22: 0.73106849 | D22: =B22-C22 | E22: =Reference!L12 | F22: -306.32868 | G22: =E22-F22 | H22: =Reference!O12 | I22: 177.48858 | J22: =H22-I22 | K22: =Reference!P12 | L22: 31.326961 | M22: =K22-L22
A23: 5 | B23: =Reference!E13 | C23: 0.6869026 | D23: =B23-C23 | E23: =Reference!L13 | F23: -192.32483 | G23: =E23-F23 | H23: =Reference!O13 | I23: 304.70707 | J23: =H23-I23 | K23: =Reference!P13 | L23: 35.947313 | M23: =K23-L23
A24: 6 | B24: =Reference!E14 | C24: 0.65223422 | D24: =B24-C24 | E24: =Reference!L14 | F24: -83.714435 | G24: =E24-F24 | H24: =Reference!O14 | I24: 417.58182 | J24: =H24-I24 | K24: =Reference!P14 | L24: 42.555531 | M24: =K24-L24
A25: 7 | B25: =Reference!E15 | C25: 0.6192944 | D25: =B25-C25 | E25: =Reference!L15 | F25: 22.791215 | G25: =E25-F25 | H25: =Reference!O15 | I25: 521.77082 | J25: =H25-I25 | K25: =Reference!P15 | L25: 48.719933 | M25: =K25-L25
A26: 8 | B26: =Reference!E16 | C26: 0.58799553 | D26: =B26-C26 | E26: =Reference!L16 | F26: 125.83751 | G26: =E26-F26 | H26: =Reference!O16 | I26: 615.83061 | J26: =H26-I26 | K26: =Reference!P16 | L26: 54.3753 | M26: =K26-L26
A27: 9 | B27: =Reference!E17 | C27: 0.55825384 | D27: =B27-C27 | E27: =Reference!L17 | F27: 223.57927 | G27: =E27-F27 | H27: =Reference!O17 | I27: 697.88811 | J27: =H27-I27 | K27: =Reference!P17 | L27: 59.408363 | M27: =K27-L27
A28: 10 | B28: =Reference!E18 | C28: 0.52999049 | D28: =B28-C28 | E28: =Reference!L18 | F28: 314.20137 | G28: =E28-F28 | H28: =Reference!O18 | I28: 766.21575 | J28: =H28-I28 | K28: =Reference!P18 | L28: 63.746016 | M28: =K28-L28
A29: 11 | B29: =Reference!E19 | C29: 0.50312975 | D29: =B29-C29 | E29: =Reference!L19 | F29: 395.17089 | G29: =E29-F29 | H29: =Reference!O19 | I29: 818.45224 | J29: =H29-I29 | K29: =Reference!P19 | L29: 67.263671 | M29: =K29-L29
... A37: 19 | B37: =Reference!E27 | C37: 0.33081759 | D37: =B37-C37 | E37: =Reference!L27 | F37: 217.89959 | G37: =E37-F37 | H37: =Reference!O27 | I37: 261.98226 | J37: =H37-I37 | K37: =Reference!P27 | L37: 45.40515 | M37: =K37-L37
A39: Largest absolute difference | B39: =MAX(MAX(ABS(MIN(D5:D14)),ABS(MAX(D5:D14))),MAX(ABS(MIN(D18:D37)),ABS(MAX(D18:D37))),MAX(ABS(MIN(G18:G37)),ABS(MAX(G18:G37))),MAX(ABS(MIN(J18:J37)),ABS(MAX(J18:J37))),MAX(ABS(MIN(M18:M37)),ABS(MAX(M18:M37))))
A40: Reconciled within €0.01? | B40: =IF(B39<0.01,"YES","NO")
